Workbook

Sheet Fiche
A1: FICHE DE PERSONNAGE — Hunter × Hunter (JDR)
A2: Légende : cellules BLANCHES = à remplir (saisie) ; cellules BEIGES = calculées automatiquement (ne pas écrire dedans).
A4: 1 · Identité
A5: Nom | B5: Gon | F5: Classe | G5: Combattant
A6: Éclat | B6: 10 | C6: Palier d'Éclat | D6: =5*ROUNDDOWN(B6/5,0) | F6: Plafond carac | G6: =VLOOKUP(B6,Barèmes!$A$39:$B$44,2,TRUE)
A7: PF total | B7: 100 | C7: Niveau | D7: =ROUNDUP(B7/100,0) | F7: PV max | G7: =100*D7
A8: DI total | B8: 0 | C8: Prestige | D8: =ROUNDUP(B8/100,0) | F8: PV courants | G8: 100
A9: Arme (bonus de classe) | B9: Armes de mêlée | F9: Défense (bonus de classe) | G9: Esquive
A10: Bonus de classe du Combattant (+10 d'office) : Initiative, Lutte, Résistance à la douleur, l'arme choisie ci-dessus et la défense choisie ci-dessus. Reportés dans la colonne Bonus des compétences.
A12: 1 bis · Plafonds de formation (Combattant)
A13: Champ | B13: Plafond % | C13: PF max | F13: Champ | G13: Plafond % | H13: PF max | K13: Champ | L13: Plafond % | M13: PF max
A14: Martial | B14: 40 | C14: =ROUNDDOWN(B14*$B$7/100,0) | F14: Intellectuel | G14: 10 | H14: =ROUNDDOWN(G14*$B$7/100,0) | K14: Transport | L14: 20 | M14: =ROUNDDOWN(L14*$B$7/100,0)
A15: Athlétique | B15: 30 | C15: =ROUNDDOWN(B15*$B$7/100,0) | F15: Naturel | G15: 20 | H15: =ROUNDDOWN(G15*$B$7/100,0) | K15: Furtif | L15: 20 | M15: =ROUNDDOWN(L15*$B$7/100,0)
A16: Vital | B16: 30 | C16: =ROUNDDOWN(B16*$B$7/100,0) | F16: Sensoriel | G16: 20 | H16: =ROUNDDOWN(G16*$B$7/100,0) | K16: Artisanal | L16: 10 | M16: =ROUNDDOWN(L16*$B$7/100,0)
A17: Social | B17: 10 | C17: =ROUNDDOWN(B17*$B$7/100,0) | F17: Technique | G17: 10 | H17: =ROUNDDOWN(G17*$B$7/100,0) | K17: Artistique | L17: 10 | M17: =ROUNDDOWN(L17*$B$7/100,0)
A18: Arts martiaux et formations comptent dans le champ Martial. Le plafond s'applique aux PF totaux, et s'élève donc avec le niveau.
A20: 2 · Caractéristiques (saisie 0–30, ≤ plafond)
A21: Physique | B21: Valeur | C21: MOD | D21: Plafond | F21: Mentale | G21: Valeur | H21: MOD | I21: Plafond | K21: Point buy — création | P21: (aux. coût point-buy par carac)
A22: FOR — Force | B22: 5 | C22: =VLOOKUP(B22,Barèmes!$A$5:$B$35,2,FALSE) | D22: =$G$6 | F22: VOL — Volonté | G22: 5 | H22: =VLOOKUP(G22,Barèmes!$A$5:$B$35,2,FALSE) | I22: =$G$6 | K22: Moyenne | L22: =VLOOKUP($B$6,Barèmes!$A$48:$D$51,2,TRUE) | M22: Plafond | N22: =VLOOKUP($B$6,Barèmes!$A$48:$D$51,3,TRUE) | P22: =IF(B22<=$L$22,B22-3,($L$22-3)+(B22-$L$22)*(B22-$L$22+3)/2) | Q22: =IF(G22<=$L$22,G22-3,($L$22-3)+(G22-$L$22)*(G22-$L$22+3)/2)
A23: DEX — Dextérité | B23: 5 | C23: =VLOOKUP(B23,Barèmes!$A$5:$B$35,2,FALSE) | D23: =$G$6 | F23: LOG — Logique | G23: 5 | H23: =VLOOKUP(G23,Barèmes!$A$5:$B$35,2,FALSE) | I23: =$G$6 | K23: Budget | L23: =VLOOKUP($B$6,Barèmes!$A$48:$D$51,4,TRUE) | M23: Coût | N23: =SUM(P22:P27)+SUM(Q22:Q27) | P23: =IF(B23<=$L$22,B23-3,($L$22-3)+(B23-$L$22)*(B23-$L$22+3)/2) | Q23: =IF(G23<=$L$22,G23-3,($L$22-3)+(G23-$L$22)*(G23-$L$22+3)/2)
A24: AGI — Agilité | B24: 5 | C24: =VLOOKUP(B24,Barèmes!$A$5:$B$35,2,FALSE) | D24: =$G$6 | F24: INS — Instinct | G24: 5 | H24: =VLOOKUP(G24,Barèmes!$A$5:$B$35,2,FALSE) | I24: =$G$6 | K24: Reste | L24: =L23-N23 | M24: > plafond ? | N24: =IF(MAX(B22:B27,G22:G27)>N22,"oui","non") | P24: =IF(B24<=$L$22,B24-3,($L$22-3)+(B24-$L$22)*(B24-$L$22+3)/2) | Q24: =IF(G24<=$L$22,G24-3,($L$22-3)+(G24-$L$22)*(G24-$L$22+3)/2)
A25: END — Endurance | B25: 5 | C25: =VLOOKUP(B25,Barèmes!$A$5:$B$35,2,FALSE) | D25: =$G$6 | F25: ÉRU — Érudition | G25: 5 | H25: =VLOOKUP(G25,Barèmes!$A$5:$B$35,2,FALSE) | I25: =$G$6 | P25: =IF(B25<=$L$22,B25-3,($L$22-3)+(B25-$L$22)*(B25-$L$22+3)/2) | Q25: =IF(G25<=$L$22,G25-3,($L$22-3)+(G25-$L$22)*(G25-$L$22+3)/2)
A26: PER — Perception | B26: 5 | C26: =VLOOKUP(B26,Barèmes!$A$5:$B$35,2,FALSE) | D26: =$G$6 | F26: IMA — Imagination | G26: 5 | H26: =VLOOKUP(G26,Barèmes!$A$5:$B$35,2,FALSE) | I26: =$G$6 | P26: =IF(B26<=$L$22,B26-3,($L$22-3)+(B26-$L$22)*(B26-$L$22+3)/2) | Q26: =IF(G26<=$L$22,G26-3,($L$22-3)+(G26-$L$22)*(G26-$L$22+3)/2)
A27: PRÉ — Présence | B27: 5 | C27: =VLOOKUP(B27,Barèmes!$A$5:$B$35,2,FALSE) | D27: =$G$6 | F27: CHA — Charisme | G27: 5 | H27: =VLOOKUP(G27,Barèmes!$A$5:$B$35,2,FALSE) | I27: =$G$6 | P27: =IF(B27<=$L$22,B27-3,($L$22-3)+(B27-$L$22)*(B27-$L$22+3)/2) | Q27: =IF(G27<=$L$22,G27-3,($L$22-3)+(G27-$L$22)*(G27-$L$22+3)/2)
A28: Total caractéristiques | B28: =SUM(B22,B23,B24,B25,B26,B27,G22,G23,G24,G25,G26,G27) | C28: Repère : 5 moyenne · 9 max humain · 19 sommet · 30 au-delà
A30: 3 · Capacités physiques
A31: Actions actives / tour | B31: =MAX(1,MIN(10,ROUNDDOWN((C24+C23)/10,0))) | D31: Taille | E31: Moyenne | H31: Espace / Allonge | I31: 1 m / 1 m (Moyenne)
A32: Capacité | B32: Légère | C32: Intermédiaire | D32: Lourde | F32: Capacité | G32: Légère | H32: Intermédiaire | I32: Lourde
A33: Mouvement | B33: =VLOOKUP(B24,Barèmes!$A$89:$D$119,2,FALSE) | C33: =VLOOKUP(B24,Barèmes!$A$89:$D$119,3,FALSE) | D33: =VLOOKUP(B24,Barèmes!$A$89:$D$119,4,FALSE) | F33: Indice de poids | G33: =VLOOKUP(B22,Barèmes!$A$55:$D$85,2,FALSE) | H33: =VLOOKUP(B22,Barèmes!$A$55:$D$85,3,FALSE) | I33: =VLOOKUP(B22,Barèmes!$A$55:$D$85,4,FALSE)
A34: Apnée | B34: =VLOOKUP(B25,Barèmes!$A$123:$D$153,2,FALSE) | C34: =VLOOKUP(B25,Barèmes!$A$123:$D$153,3,FALSE) | D34: =VLOOKUP(B25,Barèmes!$A$123:$D$153,4,FALSE) | F34: Tirer / pousser | G34: =indice de poids × 10 (chaque colonne)
A35: Suffocation | B35: =B25 | C35: rounds avant inconscience ; mort à 2 × END | F35: Mort (suffocation) | G35: =2*B25 | H35: rounds (pleine respiration → mort)
A37: 4 · Combat
A38: Actions actives / tour | B38: =$B$31 | D38: PV max | E38: =$G$7 | G38: PV courants | H38: =$G$8
A40: Réduction de dégâts (armure) | B40: CON | C40: TRA | D40: PER | E40: FEU | F40: FRO | G40: ÉLE | H40: DÉC
B41: 0 | C41: 0 | D41: 0 | E41: 0 | F41: 0 | G41: 0 | H41: 0
A42: Jets de combat — Initiative, attaque avec l'arme (Armes de mêlée / jet / Archerie / feu), Parade, Esquive, Lutte : voir la section Compétences.
A44: Arme équipée | B44: Nom | C44: Dégâts faciaux | D44: Mult. N (0–3) | F44: Finesse | G44: Type | H44: Dégâts de base
B45: Mains nues | C45: 20 | D45: 1 | F45: Non | G45: CON | H45: =C45+D45*IF(F45="Oui",C23,C22)
A46: Dégâts infligés = (Dégâts de base − réduction de dégâts du type) × marge% ; la réduction se retire avant le multiplicateur.
A48: 5 · Aura & Nen
...

Sheet Barèmes
A1: BARÈMES — tables de correspondance (feuille de calcul, ne pas modifier)
A3: MOD carac (valeur 0–30 → modificateur)
A4: Valeur | B4: MOD
A5: 0 | B5: -25
A6: 1 | B6: -20
A7: 2 | B7: -15
A8: 3 | B8: -10
A9: 4 | B9: -5
A10: 5 | B10: 0
A11: 6 | B11: 5
A12: 7 | B12: 5
A13: 8 | B13: 5
A14: 9 | B14: 5
A15: 10 | B15: 10
A16: 11 | B16: 10
... A35: 30 | B35: 50
A37: Plafond carac par Éclat
A38: Éclat ≥ | B38: Plafond
A39: 0 | B39: 9
A40: 10 | B40: 14
A41: 20 | B41: 19
A42: 30 | B42: 24
A43: 40 | B43: 29
A44: 50 | B44: 30
A46: Création par Éclat (moyenne / plafond / budget)
A47: Éclat ≥ | B47: Moyenne | C47: Plafond | D47: Budget
A48: 0 | B48: 5 | C48: 7 | D48: 24
A49: 15 | B49: 7 | C49: 9 | D49: 48
A50: 30 | B50: 9 | C50: 11 | D50: 72
A51: 45 | B51: 11 | C51: 13 | D51: 96
A53: Indice de poids (FOR → Légère / Inter / Lourde)
A54: FOR | B54: Légère | C54: Intermédiaire | D54: Lourde
A55: 0 | B55: 0 kg | C55: 0 kg | D55: 0 kg
A56: 1 | B56: 1 kg | C56: 2 kg | D56: 5 kg
A57: 2 | B57: 2 kg | C57: 5 kg | D57: 10 kg
A58: 3 | B58: 3 kg | C58: 8 kg | D58: 20 kg
A59: 4 | B59: 5 kg | C59: 15 kg | D59: 50 kg
A60: 5 | B60: 10 kg | C60: 30 kg | D60: 100 kg
A61: 6 | B61: 20 kg | C61: 60 kg | D61: 200 kg
A62: 7 | B62: 30 kg | C62: 100 kg | D62: 300 kg
...

Sheet Référence
A1: RÉFÉRENCE — aide-mémoire (consultatif)
A3: Échelle de difficulté
A4: Palier | B4: Seuil
A5: Triviale | B5: 0
A6: Très facile | B6: 20
A7: Facile | B7: 40
A8: Moyenne | B8: 80
A9: Difficile | B9: 120
A10: Très difficile | B10: 180
A11: Absurde | B11: 240
A12: Quasi impossible | B12: 320
A13: Impossible | B13: 400
A14: Surhumaine | B14: 520
A15: Prodigieuse | B15: 640
A16: Insurmontable | B16: 780
A17: Inimaginable | B17: 920
A19: Types de dégâts (7)
A20: Sigle | B20: Nom | C20: Famille | D20: Exemples
A21: CON | B21: Contondant | C21: Physique | D21: Masses, poings, chutes
A22: TRA | B22: Tranchant | C22: Physique | D22: Lames, griffes, fil de Nen
A23: PER | B23: Perforant | C23: Physique | D23: Pointes, flèches, balles
A24: FEU | B24: Feu | C24: Élémentaire | D24: Feu, lave, vapeur
A25: FRO | B25: Froid | C25: Élémentaire | D25: Glace, gel
A26: ÉLE | B26: Électrique | C26: Élémentaire | D26: Foudre, décharges, lumière
A27: DÉC | B27: Décomposition | C27: Élémentaire | D27: Corruption, acide, ténèbres
A29: Marge (% de touche)
A30: Condition | B30: Effet
A31: ≥ 200 | B31: 200 % (×2, plafond)
A32: 10 à 199 | B32: ce % de touche
A33: 0 à 9 | B33: touche mais 0 dégât
A34: < 0 | B34: raté
A36: Postures de combat
A37: Posture | B37: Attaque | C37: Défense
A38: Défensive partielle | B38: −30 | C38: +10
A39: Défensive totale | B39: aucune att. | C39: +30
A40: Offensive partielle | B40: +10 | C40: −30
A41: Offensive totale | B41: +30 | C41: aucune déf.
A43: Situations
A44: Situation | B44: Init | C44: Att | D44: Esq | E44: Par | F44: Phys
A45: De dos | B45: – | C45: −30 | D45: −80 | E45: −80 | F45: –
...
